<?xml version="1.0"?>

<robot name="joinedrobot" 
  xmlns:xacro="http://wiki.ros.org/xacro">

    <xacro:arg name="robot_namespace" default="" />

    <!-- scout 2.0 -->
    <xacro:include filename="$(find scout_description)/urdf/scout_v2.xacro"/>
        
    <!-- ur5e -->
    <xacro:include filename="$(find ur_e_description)/urdf/ur5e.urdf.xacro" />
    
    <!-- arm -->
    <xacro:arg name="kinematics_config" default="$(find ur_e_description)/config/ur5e_default.yaml"/>
    <xacro:arg name="prefix" default="arm_"/>
    <xacro:ur5e_robot prefix="$(arg prefix)" joint_limited="true" kinematics_file="${load_yaml('$(arg kinematics_config)')}"/>   
  
    <link name="world"/>

    <!-- <joint name="world_odom" type="fixed">
        <parent link="world"/>
        <child link="odom"/>
        <origin xyz="0 0 0" rpy="0 0 0" />
    </joint> -->

    <joint name="world_joint" type="floating">
        <parent link="world"/>
        <child link="base_link"/>
        <origin xyz="0 0 0" rpy="0 0 0" />
        <!-- <axis xyz="0 0 1" /> -->
    </joint>


    <joint name="joined_joint" type="fixed">
        <parent link="base_link"/>
        <child link="$(arg prefix)base_link"/>
        <origin xyz="0 0 0.13" rpy="0 0 0" />
        
    </joint>

</robot>
