<?xml version="1.0"?>

<robot name="joinedrobot" 
  xmlns:xacro="http://wiki.ros.org/xacro">

    <xacro:arg name="robot_namespace" default="/" />

    <!-- scout 2.0 -->
    <!-- <xacro:include filename="$(find scout_description)/urdf/scout_v2.xacro"/> -->
    <xacro:include filename="$(find joined_scout_ur5e)/urdf/scout_v2.xacro"/>
        
    <!-- ur5e -->
    <!-- <xacro:include filename="$(find ur_e_description)/urdf/ur5e.urdf.xacro" /> -->
    <xacro:include filename="$(find joined_scout_ur5e)/urdf/ur5e.urdf.xacro" />
    
    <!-- arm -->
    <xacro:include filename="$(find ur_e_description)/urdf/common.gazebo.xacro" />
    <xacro:arg name="kinematics_config" default="$(find ur_e_description)/config/ur5e_default.yaml"/>
    <xacro:arg name="prefix" default="arm_"/>
    <xacro:ur5e_robot prefix="$(arg prefix)" joint_limited="true" kinematics_file="${load_yaml('$(arg kinematics_config)')}"/>   
    
    <link name="world"/>
    
    <joint name="ur_joint" type="fixed">
        <parent link="scout_world"/>
        <child link="ur_world"/>
        <origin xyz="0 0 0.105" rpy="0 0 0" />
    </joint>

    <joint name="scout_joint" type="floating">
        <parent link="world"/>
        <child link="scout_world"/>
        <origin xyz="0 0 0" rpy="0 0 0" />
    </joint>


    <link name="scout_world"/>
    <joint name="world_joint" type="fixed">
        <parent link="scout_world"/>
        <child link="base_link"/>
        <origin xyz="0 0 0" rpy="0 0 0" />
    </joint>

    <link name="ur_world"/>
    <joint name="joined_joint" type="fixed">
        <parent link="ur_world"/>
        <child link="$(arg prefix)base_link"/>
        <origin xyz="0 0 0" rpy="0 0 0" />
    </joint>

</robot>
